Workbook

Sheet README
A1: Australian International Trade, 2016 to 2025
A2: 32146 Visual Analytics, Assessment Task 3. Student 24503993.
A4: How to read this workbook
A5: Every number in the analysis sheets is a live formula. The two dataset sheets hold the source data and no formula.
A6: All money values are in $ Millions, which is the unit the source uses.
A7: The focus main category is 3, Mineral fuels, lubricants and related materials.
A8: The focus subcategory is 33, Petroleum, petroleum products and related materials.
A9: Growth, share and CAGR columns are fractions shown as percentages.
A10: The dashboard and the storyboard read this workbook, so a change here changes the charts.
A12: The dashboard and the storyboard
A13: The live dashboard and storyboard URL is printed on the report title page.
A15: Sheets
A16: Sheet | B16: What it holds
A17: Keys | B17: Numeric year keys that the trend and forecast formulas read.
A18: Export-dataset | B18: The source export data, copied without any change.
A19: Import-dataset | B19: The source import data, copied without any change.
A20: Export-tidy | B20: The export data in long format, one row per category and year.
A21: Import-tidy | B21: The import data in long format, one row per category and year.
A22: Main-Analytics | B22: Growth, index, share, CAGR and growth contribution for the 10 main categories.
A23: Main-Stats | B23: Mean, median, spread, trend and the outlier z-score for the 10 main categories.
A24: Balance | B24: Export minus import, and the cover ratio, by main category.
A25: Correlation | B25: How the main categories move against each other.
A26: ChangePoints | B26: The largest rise and the largest fall in each year, with a possible cause.
A27: Cat3-SubAnalytics | B27: Main category 3 against subcategories 32, 33 and 34.
... A38: Chart-Pet33 | B38: The focus subcategory. Export against import, the balance, and the forecast.

Sheet Keys
A1: Numeric keys used by the trend and forecast formulas
A2: Index | B2: Year | C2: Forecast year
A3: 1 | B3: 2016 | C3: 2026
A4: 2 | B4: 2017 | C4: 2027
A5: 3 | B5: 2018 | C5: 2028
A6: 4 | B6: 2019 | C6: 2029
A7: 5 | B7: 2020 | C7: 2030
A8: 6 | B8: 2021
A9: 7 | B9: 2022
A10: 8 | B10: 2023
A11: 9 | B11: 2024
A12: 10 | B12: 2025

Sheet Export-dataset
A1: Export | B1: 0 Food and live animals ; | C1: 00 Live animals (excl. fish (not marine mammals) crustaceans, molluscs and aquatic invertebrates of SITC Division 03) ; | D1: 01 Meat and meat preparations ; | E1: 02 Dairy products and birds’ eggs ; | F1: 03 Fish (excl. marine mammals) crustaceans, molluscs and aquatic invertebrates, and preparations thereof (excl. extracts and juices of fish, crustaceans, molluscs or other aquatic invertebrates, prepared or preserved of SITC 01710) ; | G1: 04 Cereals and cereal preparations ; | H1: 05 Vegetables and fruit ; | I1: 06 Sugars, sugar preparations and honey ; | J1: 07 Coffee, tea, cocoa, spices, and manufactures thereof ; | K1: 08 Feeding stuff for animals (excl. unmilled cereals) ; | L1: 09 Miscellaneous edible products and preparations ; | M1: 1 Beverages and tobacco ; | N1: 11 Beverages ; | O1: 12 Tobacco and tobacco manufactures ; | P1: 2 Crude materials, inedible, except fuels ; | Q1: 21 Hides, skins and furskins, raw ; | R1: 22 Oil-seeds and oleaginous fruits ; | S1: 23 Crude rubber (incl. synthetic and reclaimed) ; | T1: 24 Cork and wood ; | U1: 25 Pulp and waste paper ; | V1: 26 Textile fibres (excl. wool tops and other combed wool) and their wastes, not manufactured into yarn or fabric ; | W1: 27 Crude fertilizers (excl. those of Division 56) and crude minerals (excl. coal, petroleum and precious stones) ; | X1: 28 Metalliferous ores and metal scrap ; | Y1: 29 Crude animal and vegetable materials, nes ; | Z1: 3 Mineral fuels, lubricants and related materials ; | AA1: 32 Coal, coke and briquettes ; | AB1: 33 Petroleum, petroleum products and related materials ; | AC1: 34 Gas, natural and manufactured ; | AD1: 4 Animal and vegetable oils, fats and waxes ; | AE1: 41 Animal oils and fats ; | AF1: 42 Fixed vegetable fats and oils, crude, refined or fractionated ; | AG1: 43 Animal or vegetable fats and oils, processed; waxes of animal or vegetable origin; inedible mixtures or preparations of animal or vegetable fats or oils, nes ; | AH1: 5 Chemicals and related products, nes ; | AI1: 51 Organic chemicals ; | AJ1: 52 Inorganic chemicals ; | AK1: 53 Dyeing, tanning and colouring materials ; | AL1: 54 Medicinal and pharmaceutical products ; | AM1: 55 Essential oils and resinoids and perfume materials; toilet, polishing and cleansing preparations ; | AN1: 56 Fertilisers (excl. those of group 272) ; | AO1: 57 Plastics in primary forms ; | AP1: 58 Plastics in non-primary forms ; | AQ1: 59 Chemical materials and products, nes ; | AR1: 6 Manufactured goods classified chiefly by material ; | AS1: 61 Leather, leather manufactures, nes, and dressed furskins ; | AT1: 62 Rubber manufactures, nes ; | AU1: 63 Cork and wood manufactures (excl. furniture) ; | AV1: 64 Paper, paperboard and articles of paper pulp, of paper or of paperboard ; | AW1: 65 Textile yarn, fabrics, made-up articles nes, and related products ; | AX1: 66 Non-metallic mineral manufactures, nes ; | AY1: 67 Iron and steel ; | AZ1: 68 Non-ferrous metals ; | BA1: 69 Manufactures of metals, nes ; | BB1: 7 Machinery and transport equipment ; | BC1: 71 Power generating machinery and equipment ; | BD1: 72 Machinery specialized for particular industries ; | BE1: 73 Metalworking machinery ; | BF1: 74 General industrial machinery and equipment, nes, and machine parts, nes ; | BG1: 75 Office machines and automatic data processing machines ; | BH1: 76 Telecommunications and sound recording and reproducing apparatus and equipment ; | BI1: 77 Electrical machinery, apparatus and appliances, nes, and electrical parts thereof (incl. non electrical counterparts, nes, of electrical household type equipment) ; | BJ1: 78 Road vehicles (incl. air-cushion vehicles) ; | BK1: 79 Transport equipment (excl. road vehicles) ; | BL1: 8 Miscellaneous manufactured articles ; | BM1: 81 Prefabricated buildings and sanitary, plumbing, heating and lighting fixtures and fittings, nes ; | BN1: 82 Furniture and parts thereof; bedding, mattresses, mattress supports, cushions and similar stuffed furnishings ; | BO1: 83 Travel goods, handbags and similar containers ; | BP1: 84 Articles of apparel and clothing accessories ; | BQ1: 85 Footwear ; | BR1: 87 Professional, scientific and controlling instruments and apparatus, nes ; | BS1: 88 Photographic apparatus, equipment and supplies and optical goods, nes; watches and clocks ; | BT1: 89 Miscellaneous manufactured articles, nes ; | BU1: 9 Commodities and transactions not classified elsewhere in the SITC ; | BV1: 93 Special transactions and commodities not classified according to kind ; | BW1: 95 Gold coin whether or not legal tender, and other coin being legal tender ; | BX1: 96 Coin (excl. gold coin) not being legal tender ; | BY1: 97 Gold, non-monetary (excl. gold ores and concentrates) ; | BZ1: 98 Combined confidential items excluding some of SITC 28099 (exports only) and some of SITC 51099 (imports only) ; | CA1: -1 TOTAL ;
A2: Unit | B2: $ Millions | C2: $ Millions | D2: $ Millions | E2: $ Millions | F2: $ Millions | G2: $ Millions | H2: $ Millions | I2: $ Millions | J2: $ Millions | K2: $ Millions | L2: $ Millions | M2: $ Millions | N2: $ Millions | O2: $ Millions | P2: $ Millions | Q2: $ Millions | R2: $ Millions | S2: $ Millions | T2: $ Millions | U2: $ Millions | V2: $ Millions | W2: $ Millions | X2: $ Millions | Y2: $ Millions | Z2: $ Millions | AA2: $ Millions | AB2: $ Millions | AC2: $ Millions | AD2: $ Millions | AE2: $ Millions | AF2: $ Millions | AG2: $ Millions | AH2: $ Millions | AI2: $ Millions | AJ2: $ Millions | AK2: $ Millions | AL2: $ Millions | AM2: $ Millions | AN2: $ Millions | AO2: $ Millions | AP2: $ Millions | AQ2: $ Millions | AR2: $ Millions | AS2: $ Millions | AT2: $ Millions | AU2: $ Millions | AV2: $ Millions | AW2: $ Millions | AX2: $ Millions | AY2: $ Millions | AZ2: $ Millions | BA2: $ Millions | BB2: $ Millions | BC2: $ Millions | BD2: $ Millions | BE2: $ Millions | BF2: $ Millions | BG2: $ Millions | BH2: $ Millions | BI2: $ Millions | BJ2: $ Millions | BK2: $ Millions | BL2: $ Millions | BM2: $ Millions | BN2: $ Millions | BO2: $ Millions | BP2: $ Millions | BQ2: $ Millions | BR2: $ Millions | BS2: $ Millions | BT2: $ Millions | BU2: $ Millions | BV2: $ Millions | BW2: $ Millions | BX2: $ Millions | BY2: $ Millions | BZ2: $ Millions | CA2: $ Millions
A3: Series ID | B3: A1827804K | C3: A1827805L | D3: A1827806R | E3: A1827807T | F3: A1827808V | G3: A1827809W | H3: A1827810F | I3: A1827811J | J3: A1827812K | K3: A1827813L | L3: A1827814R | M3: A1827815T | N3: A1827816V | O3: A1827817W | P3: A1827818X | Q3: A1827819A | R3: A1827820K | S3: A1827821L | T3: A1827822R | U3: A1827823T | V3: A1827824V | W3: A1827825W | X3: A1827826X | Y3: A1827827A | Z3: A1827828C | AA3: A1827829F | AB3: A1827830R | AC3: A1827831T | AD3: A1827832V | AE3: A1827833W | AF3: A1827834X | AG3: A1827835A | AH3: A1827836C | AI3: A1827837F | AJ3: A1827838J | AK3: A1827839K | AL3: A1827840V | AM3: A1827841W | AN3: A1827842X | AO3: A1827843A | AP3: A1827844C | AQ3: A1827845F | AR3: A1827846J | AS3: A1827847K | AT3: A1827848L | AU3: A1827849R | AV3: A1827850X | AW3: A1827851A | AX3: A1827852C | AY3: A1827853F | AZ3: A1827854J | BA3: A1827855K | BB3: A1827856L | BC3: A1827857R | BD3: A1827858T | BE3: A1827859V | BF3: A1827860C | BG3: A1827861F | BH3: A1827862J | BI3: A1827863K | BJ3: A1827864L | BK3: A1827865R | BL3: A1827866T | BM3: A1827867V | BN3: A1827868W | BO3: A1827869X | BP3: A1827870J | BQ3: A1827871K | BR3: A1827872L | BS3: A1827873R | BT3: A1827874T | BU3: A1827875V | BV3: A1827876W | BW3: A1827877X | BX3: A1827878A | BY3: A1827879C | BZ3: A1827880L | CA3: A1827881R
A4: Y2016 | B4: 32621 | C4: 1874 | D4: 11088 | E4: 2208 | F4: 1379 | G4: 7580 | H4: 4153 | I4: 319 | J4: 363 | K4: 1174 | L4: 2478 | M4: 2679 | N4: 2610 | O4: 68 | P4: 83621 | Q4: 827 | R4: 1415 | S4: 7 | T4: 1769 | U4: 242 | V4: 4722 | W4: 665 | X4: 73494 | Y4: 476 | Z4: 67702 | AA4: 42273 | AB4: 6946 | AC4: 18480 | AD4: 675 | AE4: 422 | AF4: 217 | AG4: 37 | AH4: 8367 | AI4: 227 | AJ4: 657 | AK4: 847 | AL4: 3486 | AM4: 985 | AN4: 369 | AO4: 315 | AP4: 418 | AQ4: 1065 | AR4: 13406 | AS4: 184 | AT4: 246 | AU4: 111 | AV4: 984 | AW4: 268 | AX4: 1060 | AY4: 602 | AZ4: 8842 | BA4: 1107 | BB4: 15387 | BC4: 872 | BD4: 1872 | BE4: 161 | BF4: 2269 | BG4: 1542 | BH4: 1752 | BI4: 1691 | BJ4: 2940 | BK4: 2290 | BL4: 6558 | BM4: 136 | BN4: 133 | BO4: 64 | BP4: 328 | BQ4: 92 | BR4: 2532 | BS4: 409 | BT4: 2862 | BU4: 27452 | BV4: 1563 | BW4: 989 | BX4: 1 | BY4: 18857 | BZ4: 6043 | CA4: 258469
A5: Y2017 | B5: 36596 | C5: 1618 | D5: 11834 | E5: 2345 | F5: 1424 | G5: 9336 | H5: 5099 | I5: 330 | J5: 369 | K5: 1230 | L5: 3011 | M5: 3031 | N5: 2962 | O5: 67 | P5: 99473 | Q5: 808 | R5: 1906 | S5: 0 | T5: 1975 | U5: 277 | V5: 5852 | W5: 1575 | X5: 86583 | Y5: 496 | Z5: 91149 | AA5: 57133 | AB5: 7662 | AC5: 26355 | AD5: 680 | AE5: 390 | AF5: 241 | AG5: 49 | AH5: 8643 | AI5: 199 | AJ5: 702 | AK5: 959 | AL5: 3478 | AM5: 1180 | AN5: 265 | AO5: 339 | AP5: 443 | AQ5: 1072 | AR5: 14749 | AS5: 166 | AT5: 294 | AU5: 115 | AV5: 1013 | AW5: 274 | AX5: 902 | AY5: 917 | AZ5: 9957 | BA5: 1114 | BB5: 14638 | BC5: 742 | BD5: 1886 | BE5: 188 | BF5: 2191 | BG5: 1226 | BH5: 2012 | BI5: 1847 | BJ5: 2264 | BK5: 2283 | BL5: 6857 | BM5: 144 | BN5: 141 | BO5: 70 | BP5: 328 | BQ5: 115 | BR5: 2619 | BS5: 427 | BT5: 3017 | BU5: 25523 | BV5: 1474 | BW5: 677 | BX5: 1 | BY5: 17620 | BZ5: 5749 | CA5: 301334
A6: Y2018 | B6: 35271 | C6: 1825 | D6: 13605 | E6: 2481 | F6: 1469 | G6: 7326 | H6: 3567 | I6: 300 | J6: 393 | K6: 1359 | L6: 2946 | M6: 3377 | N6: 3318 | O6: 59 | P6: 106879 | Q6: 731 | R6: 1398 | S6: 15 | T6: 2218 | U6: 238 | V6: 6474 | W6: 2110 | X6: 93112 | Y6: 584 | Z6: 122269 | AA6: 66848 | AB6: 11191 | AC6: 44229 | AD6: 663 | AE6: 368 | AF6: 240 | AG6: 55 | AH6: 10510 | AI6: 201 | AJ6: 937 | AK6: 1029 | AL6: 4750 | AM6: 1346 | AN6: 320 | AO6: 298 | AP6: 443 | AQ6: 1185 | AR6: 17031 | AS6: 166 | AT6: 307 | AU6: 97 | AV6: 1145 | AW6: 273 | AX6: 927 | AY6: 1029 | AZ6: 11823 | BA6: 1265 | BB6: 15352 | BC6: 939 | BD6: 1833 | BE6: 275 | BF6: 2296 | BG6: 1284 | BH6: 2008 | BI6: 2078 | BJ6: 1693 | BK6: 2945 | BL6: 7288 | BM6: 162 | BN6: 152 | BO6: 80 | BP6: 336 | BQ6: 124 | BR6: 2765 | BS6: 440 | BT6: 3231 | BU6: 25975 | BV6: 1371 | BW6: 814 | BX6: 0 | BY6: 19136 | BZ6: 4651 | CA6: 344615
A7: Y2019 | B7: 37649 | C7: 2126 | D7: 16462 | E7: 2488 | F7: 1529 | G7: 5891 | H7: 4112 | I7: 268 | J7: 425 | K7: 1374 | L7: 2977 | M7: 3582 | N7: 3523 | O7: 59 | P7: 136415 | Q7: 579 | R7: 1051 | S7: 20 | T7: 2225 | U7: 183 | V7: 4844 | W7: 1717 | X7: 125211 | Y7: 584 | Z7: 126288 | AA7: 63941 | AB7: 12224 | AC7: 50124 | AD7: 647 | AE7: 359 | AF7: 243 | AG7: 47 | AH7: 11971 | AI7: 212 | AJ7: 754 | AK7: 1008 | AL7: 6249 | AM7: 1532 | AN7: 262 | AO7: 328 | AP7: 397 | AQ7: 1225 | AR7: 17567 | AS7: 141 | AT7: 325 | AU7: 108 | AV7: 1094 | AW7: 305 | AX7: 1005 | AY7: 1217 | AZ7: 11999 | BA7: 1372 | BB7: 16992 | BC7: 1064 | BD7: 1961 | BE7: 192 | BF7: 2456 | BG7: 1410 | BH7: 2657 | BI7: 2131 | BJ7: 1919 | BK7: 3208 | BL7: 8208 | BM7: 157 | BN7: 182 | BO7: 94 | BP7: 377 | BQ7: 122 | BR7: 3906 | BS7: 466 | BT7: 2901 | BU7: 30661 | BV7: 1239 | BW7: 861 | BX7: 0 | BY7: 23372 | BZ7: 5188 | CA7: 389981
A8: Y2020 | B8: 35628 | C8: 1949 | D8: 14705 | E8: 2544 | F8: 1229 | G8: 6440 | H8: 4127 | I8: 283 | J8: 447 | K8: 1310 | L8: 2591 | M8: 3283 | N8: 3246 | O8: 37 | P8: 151968 | Q8: 414 | R8: 1183 | S8: 10 | T8: 1669 | U8: 172 | V8: 2739 | W8: 1163 | X8: 144068 | Y8: 551 | Z8: 88821 | AA8: 43367 | AB8: 7755 | AC8: 37699 | AD8: 761 | AE8: 444 | AF8: 282 | AG8: 33 | AH8: 11092 | AI8: 227 | AJ8: 641 | AK8: 894 | AL8: 5547 | AM8: 1590 | AN8: 330 | AO8: 232 | AP8: 311 | AQ8: 1325 | AR8: 14708 | AS8: 112 | AT8: 260 | AU8: 103 | AV8: 934 | AW8: 276 | AX8: 736 | AY8: 920 | AZ8: 10215 | BA8: 1154 | BB8: 14678 | BC8: 1068 | BD8: 1769 | BE8: 138 | BF8: 2164 | BG8: 1300 | BH8: 2251 | BI8: 2006 | BJ8: 1598 | BK8: 2387 | BL8: 7376 | BM8: 161 | BN8: 136 | BO8: 112 | BP8: 387 | BQ8: 129 | BR8: 3526 | BS8: 432 | BT8: 2494 | BU8: 34408 | BV8: 1063 | BW8: 1303 | BX8: 2 | BY8: 25492 | BZ8: 6551 | CA8: 362728
A9: Y2021 | B9: 43540 | C9: 1646 | D9: 14801 | E9: 2947 | F9: 1207 | G9: 14105 | H9: 4512 | I9: 318 | J9: 476 | K9: 1424 | L9: 2105 | M9: 2523 | N9: 2503 | O9: 21 | P9: 198179 | Q9: 504 | R9: 3166 | S9: 11 | T9: 1338 | U9: 266 | V9: 5081 | W9: 1948 | X9: 185259 | Y9: 613 | Z9: 126395 | AA9: 63504 | AB9: 11715 | AC9: 51179 | AD9: 1085 | AE9: 669 | AF9: 360 | AG9: 54 | AH9: 10052 | AI9: 239 | AJ9: 808 | AK9: 1036 | AL9: 3630 | AM9: 1663 | AN9: 490 | AO9: 368 | AP9: 345 | AQ9: 1474 | AR9: 16703 | AS9: 160 | AT9: 257 | AU9: 96 | AV9: 948 | AW9: 333 | AX9: 570 | AY9: 793 | AZ9: 12328 | BA9: 1220 | BB9: 14728 | BC9: 872 | BD9: 1678 | BE9: 175 | BF9: 2230 | BG9: 1376 | BH9: 2331 | BI9: 2227 | BJ9: 1853 | BK9: 1988 | BL9: 8036 | BM9: 203 | BN9: 145 | BO9: 116 | BP9: 480 | BQ9: 119 | BR9: 3875 | BS9: 453 | BT9: 2646 | BU9: 36933 | BV9: 1789 | BW9: 2576 | BX9: 2 | BY9: 23281 | BZ9: 9283 | CA9: 458168
A10: Y2022 | B10: 53122 | C10: 1518 | D10: 16600 | E10: 3385 | F10: 1205 | G10: 20672 | H10: 5027 | I10: 321 | J10: 517 | K10: 1719 | L10: 2160 | M10: 2572 | N10: 2553 | O10: 19 | P10: 188296 | Q10: 454 | R10: 7762 | S10: 9 | T10: 1523 | U10: 307 | V10: 7710 | W10: 12384 | X10: 157451 | Y10: 692 | Z10: 251334 | AA10: 142345 | AB10: 17341 | AC10: 91648 | AD10: 1682 | AE10: 1080 | AF10: 538 | AG10: 64 | AH10: 12575 | AI10: 245 | AJ10: 1675 | AK10: 1068 | AL10: 4328 | AM10: 1768 | AN10: 731 | AO10: 303 | AP10: 451 | AQ10: 2007 | AR10: 19431 | AS10: 148 | AT10: 363 | AU10: 96 | AV10: 1014 | AW10: 356 | AX10: 604 | AY10: 1340 | AZ10: 14078 | BA10: 1430 | BB10: 16516 | BC10: 1027 | BD10: 1911 | BE10: 260 | BF10: 2489 | BG10: 1545 | BH10: 2337 | BI10: 2692 | BJ10: 2013 | BK10: 2245 | BL10: 9077 | BM10: 175 | BN10: 166 | BO10: 201 | BP10: 649 | BQ10: 141 | BR10: 4409 | BS10: 506 | BT10: 2834 | BU10: 39255 | BV10: 764 | BW10: 3046 | BX10: 9 | BY10: 23514 | BZ10: 11921 | CA10: 593865
A11: Y2023 | B11: 54749 | C11: 1236 | D11: 17798 | E11: 3000 | F11: 1346 | G11: 20628 | H11: 5891 | I11: 297 | J11: 509 | K11: 1737 | L11: 2314 | M11: 2548 | N11: 2524 | O11: 24 | P11: 202961 | Q11: 451 | R11: 5508 | S11: 14 | T11: 1435 | U11: 203 | V11: 7407 | W11: 19055 | X11: 168243 | Y11: 650 | Z11: 195549 | AA11: 103331 | AB11: 15760 | AC11: 76456 | AD11: 1609 | AE11: 1053 | AF11: 420 | AG11: 136 | AH11: 11484 | AI11: 221 | AJ11: 1264 | AK11: 920 | AL11: 4754 | AM11: 1686 | AN11: 338 | AO11: 277 | AP11: 385 | AQ11: 1643 | AR11: 19357 | AS11: 109 | AT11: 397 | AU11: 98 | AV11: 888 | AW11: 364 | AX11: 854 | AY11: 1256 | AZ11: 13950 | BA11: 1442 | BB11: 18604 | BC11: 1303 | BD11: 2113 | BE11: 272 | BF11: 3044 | BG11: 1489 | BH11: 2677 | BI11: 2954 | BJ11: 2180 | BK11: 2574 | BL11: 10517 | BM11: 170 | BN11: 188 | BO11: 188 | BP11: 706 | BQ11: 181 | BR11: 4871 | BS11: 576 | BT11: 3636 | BU11: 41247 | BV11: 612 | BW11: 2011 | BX11: 11 | BY11: 28352 | BZ11: 10257 | CA11: 558623
A12: Y2024 | B12: 52562 | C12: 1117 | D12: 21317 | E12: 3425 | F12: 1219 | G12: 13747 | H12: 7067 | I12: 298 | J12: 549 | K12: 1573 | L12: 2253 | M12: 3179 | N12: 3159 | O12: 20 | P12: 179588 | Q12: 532 | R12: 5005 | S12: 20 | T12: 1424 | U12: 242 | V12: 6498 | W12: 5137 | X12: 160100 | Y12: 635 | Z12: 170842 | AA12: 85445 | AB12: 15713 | AC12: 69682 | AD12: 1397 | AE12: 865 | AF12: 416 | AG12: 118 | AH12: 12272 | AI12: 215 | AJ12: 946 | AK12: 1162 | AL12: 5387 | AM12: 1705 | AN12: 437 | AO12: 294 | AP12: 412 | AQ12: 1718 | AR12: 20515 | AS12: 112 | AT12: 331 | AU12: 97 | AV12: 891 | AW12: 392 | AX12: 590 | AY12: 1332 | AZ12: 15294 | BA12: 1476 | BB12: 20484 | BC12: 1377 | BD12: 2346 | BE12: 286 | BF12: 3125 | BG12: 1580 | BH12: 2923 | BI12: 3219 | BJ12: 2259 | BK12: 3377 | BL12: 10974 | BM12: 191 | BN12: 169 | BO12: 178 | BP12: 773 | BQ12: 191 | BR12: 4081 | BS12: 611 | BT12: 4777 | BU12: 45169 | BV12: 565 | BW12: 1340 | BX12: 23 | BY12: 35703 | BZ12: 7536 | CA12: 516983
A13: Y2025 | B13: 62043 | C13: 1299 | D13: 27217 | E13: 3562 | F13: 1588 | G13: 16169 | H13: 7282 | I13: 263 | J13: 632 | K13: 1582 | L13: 2448 | M13: 3066 | N13: 3009 | O13: 58 | P13: 180651 | Q13: 546 | R13: 4616 | S13: 30 | T13: 1521 | U13: 274 | V13: 6053 | W13: 4863 | X13: 162034 | Y13: 711 | Z13: 140181 | AA13: 64478 | AB13: 14187 | AC13: 61513 | AD13: 1806 | AE13: 823 | AF13: 529 | AG13: 455 | AH13: 12141 | AI13: 251 | AJ13: 1050 | AK13: 1053 | AL13: 5138 | AM13: 1615 | AN13: 666 | AO13: 281 | AP13: 423 | AQ13: 1661 | AR13: 22719 | AS13: 108 | AT13: 345 | AU13: 77 | AV13: 871 | AW13: 375 | AX13: 480 | AY13: 1054 | AZ13: 17943 | BA13: 1465 | BB13: 22210 | BC13: 1598 | BD13: 2416 | BE13: 248 | BF13: 3253 | BG13: 1888 | BH13: 3236 | BI13: 3266 | BJ13: 2624 | BK13: 3685 | BL13: 11863 | BM13: 190 | BN13: 173 | BO13: 183 | BP13: 774 | BQ13: 187 | BR13: 4293 | BS13: 659 | BT13: 5399 | BU13: 66414 | BV13: 439 | BW13: 1873 | BX13: 17 | BY13: 59557 | BZ13: 4530 | CA13: 523098

Sheet Import-dataset
A1: Import | B1: 0 Food and live animals ; | C1: 00 Live animals (excl. fish (not marine mammals) crustaceans, molluscs and aquatic invertebrates of SITC Division 03) ; | D1: 01 Meat and meat preparations ; | E1: 02 Dairy products and birds’ eggs ; | F1: 03 Fish (excl. marine mammals) crustaceans, molluscs and aquatic invertebrates, and preparations thereof (excl. extracts and juices of fish, crustaceans, molluscs or other aquatic invertebrates, prepared or preserved of SITC 01710) ; | G1: 04 Cereals and cereal preparations ; | H1: 05 Vegetables and fruit ; | I1: 06 Sugars, sugar preparations and honey ; | J1: 07 Coffee, tea, cocoa, spices, and manufactures thereof ; | K1: 08 Feeding stuff for animals (excl. unmilled cereals) ; | L1: 09 Miscellaneous edible products and preparations ; | M1: 1 Beverages and tobacco ; | N1: 11 Beverages ; | O1: 12 Tobacco and tobacco manufactures ; | P1: 2 Crude materials, inedible, except fuels ; | Q1: 21 Hides, skins and furskins, raw ; | R1: 22 Oil-seeds and oleaginous fruits ; | S1: 23 Crude rubber (incl. synthetic and reclaimed) ; | T1: 24 Cork and wood ; | U1: 25 Pulp and waste paper ; | V1: 26 Textile fibres (excl. wool tops and other combed wool) and their wastes, not manufactured into yarn or fabric ; | W1: 27 Crude fertilizers (excl. those of Division 56) and crude minerals (excl. coal, petroleum and precious stones) ; | X1: 28 Metalliferous ores and metal scrap ; | Y1: 29 Crude animal and vegetable materials, nes ; | Z1: 3 Mineral fuels, lubricants and related materials ; | AA1: 32 Coal, coke and briquettes ; | AB1: 33 Petroleum, petroleum products and related materials ; | AC1: 34 Gas, natural and manufactured ; | AD1: 4 Animal and vegetable oils, fats and waxes ; | AE1: 41 Animal oils and fats ; | AF1: 42 Fixed vegetable fats and oils, crude, refined or fractionated ; | AG1: 43 Animal or vegetable fats and oils, processed; waxes of animal or vegetable origin; inedible mixtures or preparations of animal or vegetable fats or oils, nes ; | AH1: 5 Chemicals and related products, nes ; | AI1: 51 Organic chemicals ; | AJ1: 52 Inorganic chemicals ; | AK1: 53 Dyeing, tanning and colouring materials ; | AL1: 54 Medicinal and pharmaceutical products ; | AM1: 55 Essential oils and resinoids and perfume materials; toilet, polishing and cleansing preparations ; | AN1: 56 Fertilisers (excl. those of group 272) ; | AO1: 57 Plastics in primary forms ; | AP1: 58 Plastics in non-primary forms ; | AQ1: 59 Chemical materials and products, nes ; | AR1: 6 Manufactured goods classified chiefly by material ; | AS1: 61 Leather, leather manufactures, nes, and dressed furskins ; | AT1: 62 Rubber manufactures, nes ; | AU1: 63 Cork and wood manufactures (excl. furniture) ; | AV1: 64 Paper, paperboard and articles of paper pulp, of paper or of paperboard ; | AW1: 65 Textile yarn, fabrics, made-up articles nes, and related products ; | AX1: 66 Non-metallic mineral manufactures, nes ; | AY1: 67 Iron and steel ; | AZ1: 68 Non-ferrous metals ; | BA1: 69 Manufactures of metals, nes ; | BB1: 7 Machinery and transport equipment ; | BC1: 71 Power generating machinery and equipment ; | BD1: 72 Machinery specialized for particular industries ; | BE1: 73 Metalworking machinery ; | BF1: 74 General industrial machinery and equipment, nes, and machine parts, nes ; | BG1: 75 Office machines and automatic data processing machines ; | BH1: 76 Telecommunications and sound recording and reproducing apparatus and equipment ; | BI1: 77 Electrical machinery, apparatus and appliances, nes, and electrical parts thereof (incl. non electrical counterparts, nes, of electrical household type equipment) ; | BJ1: 78 Road vehicles (incl. air-cushion vehicles) ; | BK1: 79 Transport equipment (excl. road vehicles) ; | BL1: 8 Miscellaneous manufactured articles ; | BM1: 81 Prefabricated buildings and sanitary, plumbing, heating and lighting fixtures and fittings, nes ; | BN1: 82 Furniture and parts thereof; bedding, mattresses, mattress supports, cushions and similar stuffed furnishings ; | BO1: 83 Travel goods, handbags and similar containers ; | BP1: 84 Articles of apparel and clothing accessories ; | BQ1: 85 Footwear ; | BR1: 87 Professional, scientific and controlling instruments and apparatus, nes ; | BS1: 88 Photographic apparatus, equipment and supplies and optical goods, nes; watches and clocks ; | BT1: 89 Miscellaneous manufactured articles, nes ; | BU1: 9 Commodities and transactions not classified elsewhere in the SITC ; | BV1: 93 Special transactions and commodities not classified according to kind ; | BW1: 95 Gold coin whether or not legal tender, and other coin being legal tender ; | BX1: 96 Coin (excl. gold coin) not being legal tender ; | BY1: 97 Gold, non-monetary (excl. gold ores and concentrates) ; | BZ1: 98 Combined confidential items excluding some of SITC 28099 (exports only) and some of SITC 51099 (imports only) ; | CA1: -1 TOTAL ;
A2: Unit | B2: $ Millions | C2: $ Millions | D2: $ Millions | E2: $ Millions | F2: $ Millions | G2: $ Millions | H2: $ Millions | I2: $ Millions | J2: $ Millions | K2: $ Millions | L2: $ Millions | M2: $ Millions | N2: $ Millions | O2: $ Millions | P2: $ Millions | Q2: $ Millions | R2: $ Millions | S2: $ Millions | T2: $ Millions | U2: $ Millions | V2: $ Millions | W2: $ Millions | X2: $ Millions | Y2: $ Millions | Z2: $ Millions | AA2: $ Millions | AB2: $ Millions | AC2: $ Millions | AD2: $ Millions | AE2: $ Millions | AF2: $ Millions | AG2: $ Millions | AH2: $ Millions | AI2: $ Millions | AJ2: $ Millions | AK2: $ Millions | AL2: $ Millions | AM2: $ Millions | AN2: $ Millions | AO2: $ Millions | AP2: $ Millions | AQ2: $ Millions | AR2: $ Millions | AS2: $ Millions | AT2: $ Millions | AU2: $ Millions | AV2: $ Millions | AW2: $ Millions | AX2: $ Millions | AY2: $ Millions | AZ2: $ Millions | BA2: $ Millions | BB2: $ Millions | BC2: $ Millions | BD2: $ Millions | BE2: $ Millions | BF2: $ Millions | BG2: $ Millions | BH2: $ Millions | BI2: $ Millions | BJ2: $ Millions | BK2: $ Millions | BL2: $ Millions | BM2: $ Millions | BN2: $ Millions | BO2: $ Millions | BP2: $ Millions | BQ2: $ Millions | BR2: $ Millions | BS2: $ Millions | BT2: $ Millions | BU2: $ Millions | BV2: $ Millions | BW2: $ Millions | BX2: $ Millions | BY2: $ Millions | BZ2: $ Millions | CA2: $ Millions
A3: Series ID | B3: A1828644C | C3: A1828645F | D3: A1828646J | E3: A1828647K | F3: A1828648L | G3: A1828649R | H3: A1828650X | I3: A1828651A | J3: A1828652C | K3: A1828653F | L3: A1828654J | M3: A1828655K | N3: A1828656L | O3: A1828657R | P3: A1828658T | Q3: A1828659V | R3: A1828660C | S3: A1828661F | T3: A1828662J | U3: A1828663K | V3: A1828664L | W3: A1828665R | X3: A1828666T | Y3: A1828667V | Z3: A1828668W | AA3: A1828669X | AB3: A1828670J | AC3: A1828671K | AD3: A1828672L | AE3: A1828673R | AF3: A1828674T | AG3: A1828675V | AH3: A1828676W | AI3: A1828677X | AJ3: A1828678A | AK3: A1828679C | AL3: A1828680L | AM3: A1828681R | AN3: A1828682T | AO3: A1828683V | AP3: A1828684W | AQ3: A1828685X | AR3: A1828686A | AS3: A1828687C | AT3: A1828688F | AU3: A1828689J | AV3: A1828690T | AW3: A1828691V | AX3: A1828692W | AY3: A1828693X | AZ3: A1828694A | BA3: A1828695C | BB3: A1828696F | BC3: A1828697J | BD3: A1828698K | BE3: A1828699L | BF3: A1828700K | BG3: A1828701L | BH3: A1828702R | BI3: A1828703T | BJ3: A1828704V | BK3: A1828705W | BL3: A1828706X | BM3: A1828707A | BN3: A1828708C | BO3: A1828709F | BP3: A1828710R | BQ3: A1828711T | BR3: A1828712V | BS3: A1828713W | BT3: A1828714X | BU3: A1828715A | BV3: A1828716C | BW3: A1828717F | BX3: A1828718J | BY3: A1828719K | BZ3: A1828720V | CA3: A1828721W
A4: Y2016 | B4: 13977 | C4: 121 | D4: 780 | E4: 1075 | F4: 1852 | G4: 1265 | H4: 2601 | I4: 483 | J4: 1975 | K4: 919 | L4: 2908 | M4: 3271 | N4: 2241 | O4: 1027 | P4: 3206 | Q4: 5 | R4: 88 | S4: 102 | T4: 816 | U4: 212 | V4: 99 | W4: 311 | X4: 1017 | Y4: 551 | Z4: 23604 | AA4: 51 | AB4: 23315 | AC4: 238 | AD4: 700 | AE4: 61 | AF4: 596 | AG4: 44 | AH4: 27705 | AI4: 2410 | AJ4: 1567 | AK4: 997 | AL4: 11226 | AM4: 2938 | AN4: 1682 | AO4: 1958 | AP4: 1947 | AQ4: 2978 | AR4: 28223 | AS4: 164 | AT4: 3399 | AU4: 1305 | AV4: 2999 | AW4: 3577 | AX4: 3847 | AY4: 2532 | AZ4: 2691 | BA4: 7710 | BB4: 103332 | BC4: 4429 | BD4: 7665 | BE4: 595 | BF4: 14478 | BG4: 9773 | BH4: 14598 | BI4: 13089 | BJ4: 34412 | BK4: 4295 | BL4: 40365 | BM4: 1661 | BN4: 4276 | BO4: 1462 | BP4: 8611 | BQ4: 2202 | BR4: 6756 | BS4: 1853 | BT4: 13547 | BU4: 9962 | BV4: 4 | BW4: 41 | BX4: 7 | BY4: 7468 | BZ4: 2440 | CA4: 254345
A5: Y2017 | B5: 14304 | C5: 155 | D5: 833 | E5: 1321 | F5: 1950 | G5: 1309 | H5: 2684 | I5: 460 | J5: 2057 | K5: 939 | L5: 2593 | M5: 3285 | N5: 2280 | O5: 1006 | P5: 3544 | Q5: 3 | R5: 111 | S5: 165 | T5: 836 | U5: 232 | V5: 91 | W5: 286 | X5: 1221 | Y5: 597 | Z5: 29805 | AA5: 139 | AB5: 29365 | AC5: 303 | AD5: 702 | AE5: 56 | AF5: 591 | AG5: 53 | AH5: 28054 | AI5: 2363 | AJ5: 1578 | AK5: 1019 | AL5: 11138 | AM5: 3084 | AN5: 1640 | AO5: 2109 | AP5: 1994 | AQ5: 3131 | AR5: 28701 | AS5: 160 | AT5: 3580 | AU5: 1408 | AV5: 2935 | AW5: 3604 | AX5: 3794 | AY5: 3059 | AZ5: 2479 | BA5: 7685 | BB5: 117933 | BC5: 4763 | BD5: 8870 | BE5: 639 | BF5: 13380 | BG5: 10489 | BH5: 15584 | BI5: 14637 | BJ5: 37308 | BK5: 12266 | BL5: 40571 | BM5: 1629 | BN5: 4256 | BO5: 1537 | BP5: 8736 | BQ5: 2177 | BR5: 6544 | BS5: 1821 | BT5: 13867 | BU5: 21397 | BV5: 12 | BW5: 21 | BX5: 3 | BY5: 6220 | BZ5: 15140 | CA5: 288291
A6: Y2018 | B6: 15132 | C6: 168 | D6: 822 | E6: 1420 | F6: 2013 | G6: 1479 | H6: 2647 | I6: 483 | J6: 2031 | K6: 1100 | L6: 2970 | M6: 3541 | N6: 2480 | O6: 1063 | P6: 3985 | Q6: 2 | R6: 115 | S6: 160 | T6: 1041 | U6: 284 | V6: 99 | W6: 316 | X6: 1306 | Y6: 662 | Z6: 40512 | AA6: 178 | AB6: 39947 | AC6: 390 | AD6: 756 | AE6: 70 | AF6: 627 | AG6: 54 | AH6: 29837 | AI6: 2507 | AJ6: 1107 | AK6: 1111 | AL6: 11782 | AM6: 3595 | AN6: 1915 | AO6: 2460 | AP6: 2196 | AQ6: 3161 | AR6: 32443 | AS6: 154 | AT6: 3966 | AU6: 1596 | AV6: 3163 | AW6: 3816 | AX6: 4038 | AY6: 3901 | AZ6: 2775 | BA6: 9039 | BB6: 121404 | BC6: 5936 | BD6: 10484 | BE6: 751 | BF6: 14952 | BG6: 11907 | BH6: 17166 | BI6: 16823 | BJ6: 39091 | BK6: 4294 | BL6: 44299 | BM6: 1789 | BN6: 4874 | BO6: 1843 | BP6: 9479 | BQ6: 2324 | BR6: 7364 | BS6: 1934 | BT6: 14691 | BU6: 12140 | BV6: 5 | BW6: 30 | BX6: 7 | BY6: 6385 | BZ6: 5711 | CA6: 304050
A7: Y2019 | B7: 16938 | C7: 145 | D7: 1029 | E7: 1477 | F7: 2034 | G7: 1916 | H7: 2806 | I7: 485 | J7: 2131 | K7: 1238 | L7: 3678 | M7: 3798 | N7: 2688 | O7: 1113 | P7: 3138 | Q7: 7 | R7: 127 | S7: 147 | T7: 801 | U7: 260 | V7: 98 | W7: 286 | X7: 744 | Y7: 665 | Z7: 38794 | AA7: 203 | AB7: 38357 | AC7: 236 | AD7: 725 | AE7: 83 | AF7: 579 | AG7: 64 | AH7: 31024 | AI7: 2260 | AJ7: 1031 | AK7: 1084 | AL7: 13112 | AM7: 3865 | AN7: 2150 | AO7: 2211 | AP7: 2226 | AQ7: 3090 | AR7: 32286 | AS7: 143 | AT7: 4242 | AU7: 1517 | AV7: 3336 | AW7: 3834 | AX7: 4110 | AY7: 3271 | AZ7: 2874 | BA7: 8957 | BB7: 123286 | BC7: 6310 | BD7: 10688 | BE7: 864 | BF7: 15646 | BG7: 11737 | BH7: 17648 | BI7: 17451 | BJ7: 37286 | BK7: 5660 | BL7: 46308 | BM7: 1742 | BN7: 4983 | BO7: 1886 | BP7: 10205 | BQ7: 2564 | BR7: 7726 | BS7: 2078 | BT7: 15133 | BU7: 11251 | BV7: 5 | BW7: 33 | BX7: 2 | BY7: 6772 | BZ7: 4434 | CA7: 307549
A8: Y2020 | B8: 17607 | C8: 157 | D8: 905 | E8: 1589 | F8: 1882 | G8: 2088 | H8: 3107 | I8: 489 | J8: 2208 | K8: 1355 | L8: 3824 | M8: 3475 | N8: 2585 | O8: 891 | P8: 3257 | Q8: 7 | R8: 141 | S8: 122 | T8: 801 | U8: 240 | V8: 97 | W8: 298 | X8: 870 | Y8: 686 | Z8: 23108 | AA8: 148 | AB8: 22720 | AC8: 242 | AD8: 766 | AE8: 85 | AF8: 627 | AG8: 55 | AH8: 33291 | AI8: 2668 | AJ8: 1043 | AK8: 1084 | AL8: 13802 | AM8: 3970 | AN8: 2122 | AO8: 2138 | AP8: 2294 | AQ8: 4167 | AR8: 34399 | AS8: 135 | AT8: 4089 | AU8: 1419 | AV8: 3274 | AW8: 5896 | AX8: 3869 | AY8: 3134 | AZ8: 3596 | BA8: 8988 | BB8: 119746 | BC8: 5691 | BD8: 10600 | BE8: 751 | BF8: 15673 | BG8: 12455 | BH8: 17588 | BI8: 17885 | BJ8: 33502 | BK8: 5595 | BL8: 46038 | BM8: 1726 | BN8: 5224 | BO8: 1512 | BP8: 10186 | BQ8: 2107 | BR8: 7758 | BS8: 1879 | BT8: 15649 | BU8: 11914 | BV8: 2 | BW8: 60 | BX8: 12 | BY8: 9208 | BZ8: 2632 | CA8: 293603
A9: Y2021 | B9: 16410 | C9: 156 | D9: 966 | E9: 1438 | F9: 1874 | G9: 1727 | H9: 2837 | I9: 491 | J9: 2164 | K9: 1220 | L9: 3535 | M9: 3449 | N9: 2744 | O9: 704 | P9: 4247 | Q9: 2 | R9: 102 | S9: 134 | T9: 1051 | U9: 281 | V9: 115 | W9: 426 | X9: 1425 | Y9: 712 | Z9: 34552 | AA9: 200 | AB9: 34044 | AC9: 310 | AD9: 831 | AE9: 90 | AF9: 680 | AG9: 61 | AH9: 37021 | AI9: 3051 | AJ9: 1286 | AK9: 1152 | AL9: 14770 | AM9: 3861 | AN9: 3289 | AO9: 2677 | AP9: 2448 | AQ9: 4490 | AR9: 36977 | AS9: 174 | AT9: 4349 | AU9: 1678 | AV9: 3217 | AW9: 4692 | AX9: 4281 | AY9: 4050 | AZ9: 4056 | BA9: 10479 | BB9: 135405 | BC9: 5352 | BD9: 12971 | BE9: 971 | BF9: 16935 | BG9: 13204 | BH9: 17682 | BI9: 19654 | BJ9: 42876 | BK9: 5759 | BL9: 50131 | BM9: 1958 | BN9: 5647 | BO9: 1632 | BP9: 10984 | BQ9: 2411 | BR9: 8175 | BS9: 2067 | BT9: 17260 | BU9: 11211 | BV9: 4 | BW9: 56 | BX9: 11 | BY9: 6525 | BZ9: 4615 | CA9: 330234
A10: Y2022 | B10: 19518 | C10: 167 | D10: 1070 | E10: 1809 | F10: 2449 | G10: 2011 | H10: 3163 | I10: 565 | J10: 2566 | K10: 1660 | L10: 4063 | M10: 3850 | N10: 3170 | O10: 682 | P10: 4653 | Q10: 4 | R10: 135 | S10: 148 | T10: 1444 | U10: 365 | V10: 125 | W10: 604 | X10: 945 | Y10: 881 | Z10: 65806 | AA10: 375 | AB10: 65082 | AC10: 352 | AD10: 1094 | AE10: 128 | AF10: 888 | AG10: 76 | AH10: 51393 | AI10: 3755 | AJ10: 3401 | AK10: 1267 | AL10: 19106 | AM10: 4657 | AN10: 5706 | AO10: 3148 | AP10: 2866 | AQ10: 7484 | AR10: 44021 | AS10: 202 | AT10: 5123 | AU10: 2045 | AV10: 3802 | AW10: 5323 | AX10: 4835 | AY10: 5214 | AZ10: 5023 | BA10: 12450 | BB10: 156900 | BC10: 6250 | BD10: 15810 | BE10: 1095 | BF10: 19875 | BG10: 14727 | BH10: 20341 | BI10: 23299 | BJ10: 50050 | BK10: 5454 | BL10: 57476 | BM10: 2136 | BN10: 6266 | BO10: 2203 | BP10: 12829 | BQ10: 3104 | BR10: 9104 | BS10: 2481 | BT10: 19352 | BU10: 12292 | BV10: 3 | BW10: 80 | BX10: 17 | BY10: 6959 | BZ10: 5229 | CA10: 417002
A11: Y2023 | B11: 19684 | C11: 212 | D11: 1035 | E11: 2034 | F11: 2230 | G11: 2136 | H11: 3366 | I11: 611 | J11: 2582 | K11: 1438 | L11: 4035 | M11: 3518 | N11: 2928 | O11: 588 | P11: 3931 | Q11: 2 | R11: 120 | S11: 130 | T11: 841 | U11: 280 | V11: 119 | W11: 478 | X11: 1019 | Y11: 942 | Z11: 60651 | AA11: 306 | AB11: 60057 | AC11: 293 | AD11: 988 | AE11: 161 | AF11: 750 | AG11: 78 | AH11: 42831 | AI11: 2720 | AJ11: 2830 | AK11: 1148 | AL11: 17000 | AM11: 5168 | AN11: 3561 | AO11: 2728 | AP11: 2703 | AQ11: 4973 | AR11: 40640 | AS11: 176 | AT11: 5189 | AU11: 1733 | AV11: 3827 | AW11: 4277 | AX11: 4605 | AY11: 4746 | AZ11: 4174 | BA11: 11917 | BB11: 173355 | BC11: 7368 | BD11: 18321 | BE11: 1171 | BF11: 20852 | BG11: 12531 | BH11: 20204 | BI11: 23989 | BJ11: 62922 | BK11: 5995 | BL11: 55698 | BM11: 1960 | BN11: 5336 | BO11: 2249 | BP11: 12165 | BQ11: 2886 | BR11: 10010 | BS11: 2601 | BT11: 18494 | BU11: 12575 | BV11: 6 | BW11: 66 | BX11: 19 | BY11: 8565 | BZ11: 3917 | CA11: 413869
A12: Y2024 | B12: 22293 | C12: 201 | D12: 1251 | E12: 1935 | F12: 2405 | G12: 2526 | H12: 3913 | I12: 688 | J12: 3250 | K12: 1647 | L12: 4477 | M12: 3349 | N12: 2906 | O12: 441 | P12: 4119 | Q12: 6 | R12: 151 | S12: 141 | T12: 917 | U12: 276 | V12: 121 | W12: 362 | X12: 1143 | Y12: 1006 | Z12: 56749 | AA12: 260 | AB12: 56183 | AC12: 306 | AD12: 1257 | AE12: 204 | AF12: 973 | AG12: 78 | AH12: 45032 | AI12: 2723 | AJ12: 2683 | AK12: 1265 | AL12: 17012 | AM12: 5568 | AN12: 4652 | AO12: 2957 | AP12: 2840 | AQ12: 5337 | AR12: 43611 | AS12: 151 | AT12: 5553 | AU12: 1776 | AV12: 4210 | AW12: 4547 | AX12: 4461 | AY12: 5952 | AZ12: 4285 | BA12: 12677 | BB12: 180686 | BC12: 7929 | BD12: 15321 | BE12: 1101 | BF12: 23737 | BG12: 14902 | BH12: 20144 | BI12: 28336 | BJ12: 62025 | BK12: 7195 | BL12: 59310 | BM12: 1973 | BN12: 5994 | BO12: 2216 | BP12: 12814 | BQ12: 2948 | BR12: 10288 | BS12: 2713 | BT12: 20362 | BU12: 13470 | BV12: 1 | BW12: 57 | BX12: 18 | BY12: 9876 | BZ12: 3513 | CA12: 429873
A13: Y2025 | B13: 24515 | C13: 190 | D13: 1252 | E13: 2295 | F13: 2548 | G13: 2618 | H13: 4138 | I13: 715 | J13: 4510 | K13: 1518 | L13: 4731 | M13: 3378 | N13: 2913 | O13: 463 | P13: 5285 | Q13: 7 | R13: 145 | S13: 142 | T13: 953 | U13: 270 | V13: 127 | W13: 481 | X13: 2129 | Y13: 1030 | Z13: 53258 | AA13: 197 | AB13: 52742 | AC13: 317 | AD13: 1282 | AE13: 135 | AF13: 1052 | AG13: 94 | AH13: 47675 | AI13: 2807 | AJ13: 2888 | AK13: 1234 | AL13: 18490 | AM13: 5842 | AN13: 5109 | AO13: 2795 | AP13: 3004 | AQ13: 5504 | AR13: 45872 | AS13: 150 | AT13: 5746 | AU13: 1879 | AV13: 4117 | AW13: 4729 | AX13: 4671 | AY13: 5364 | AZ13: 5583 | BA13: 13641 | BB13: 190956 | BC13: 8883 | BD13: 14643 | BE13: 1058 | BF13: 23637 | BG13: 19183 | BH13: 21727 | BI13: 32803 | BJ13: 59473 | BK13: 9546 | BL13: 63028 | BM13: 2011 | BN13: 6346 | BO13: 2225 | BP13: 13100 | BQ13: 3120 | BR13: 10829 | BS13: 2808 | BT13: 22590 | BU13: 25622 | BV13: 6 | BW13: 71 | BX13: 22 | BY13: 20614 | BZ13: 4904 | CA13: 460866

Sheet Export-tidy
A1: Direction | B1: Year | C1: Code | D1: Level | E1: Category | F1: Unit | G1: Series ID | H1: Value ($ Millions, export)
A2: Export | B2: 2016 | C2: 0 | D2: main | E2: Food and live animals | F2: $ Millions | G2: A1827804K | H2: ='Export-dataset'!B4 -> 32621
A3: Export | B3: 2017 | C3: 0 | D3: main | E3: Food and live animals | F3: $ Millions | G3: A1827804K | H3: ='Export-dataset'!B5 -> 36596
A4: Export | B4: 2018 | C4: 0 | D4: main | E4: Food and live animals | F4: $ Millions | G4: A1827804K | H4: ='Export-dataset'!B6 -> 35271
A5: Export | B5: 2019 | C5: 0 | D5: main | E5: Food and live animals | F5: $ Millions | G5: A1827804K | H5: ='Export-dataset'!B7 -> 37649
A6: Export | B6: 2020 | C6: 0 | D6: main | E6: Food and live animals | F6: $ Millions | G6: A1827804K | H6: ='Export-dataset'!B8 -> 35628
A7: Export | B7: 2021 | C7: 0 | D7: main | E7: Food and live animals | F7: $ Millions | G7: A1827804K | H7: ='Export-dataset'!B9 -> 43540
A8: Export | B8: 2022 | C8: 0 | D8: main | E8: Food and live animals | F8: $ Millions | G8: A1827804K | H8: ='Export-dataset'!B10 -> 53122
A9: Export | B9: 2023 | C9: 0 | D9: main | E9: Food and live animals | F9: $ Millions | G9: A1827804K | H9: ='Export-dataset'!B11 -> 54749
A10: Export | B10: 2024 | C10: 0 | D10: main | E10: Food and live animals | F10: $ Millions | G10: A1827804K | H10: ='Export-dataset'!B12 -> 52562
A11: Export | B11: 2025 | C11: 0 | D11: main | E11: Food and live animals | F11: $ Millions | G11: A1827804K | H11: ='Export-dataset'!B13 -> 62043
A12: Export | B12: 2016 | C12: 00 | D12: sub | E12: Live animals (excl. fish (not marine mammals) crustaceans, molluscs and aquatic invertebrates of SITC Division 03) | F12: $ Millions | G12: A1827805L | H12: ='Export-dataset'!C4 -> 1874
A13: Export | B13: 2017 | C13: 00 | D13: sub | E13: Live animals (excl. fish (not marine mammals) crustaceans, molluscs and aquatic invertebrates of SITC Division 03) | F13: $ Millions | G13: A1827805L | H13: ='Export-dataset'!C5 -> 1618
A14: Export | B14: 2018 | C14: 00 | D14: sub | E14: Live animals (excl. fish (not marine mammals) crustaceans, molluscs and aquatic invertebrates of SITC Division 03) | F14: $ Millions | G14: A1827805L | H14: ='Export-dataset'!C6 -> 1825
A15: Export | B15: 2019 | C15: 00 | D15: sub | E15: Live animals (excl. fish (not marine mammals) crustaceans, molluscs and aquatic invertebrates of SITC Division 03) | F15: $ Millions | G15: A1827805L | H15: ='Export-dataset'!C7 -> 2126
A16: Export | B16: 2020 | C16: 00 | D16: sub | E16: Live animals (excl. fish (not marine mammals) crustaceans, molluscs and aquatic invertebrates of SITC Division 03) | F16: $ Millions | G16: A1827805L | H16: ='Export-dataset'!C8 -> 1949
A17: Export | B17: 2021 | C17: 00 | D17: sub | E17: Live animals (excl. fish (not marine mammals) crustaceans, molluscs and aquatic invertebrates of SITC Division 03) | F17: $ Millions | G17: A1827805L | H17: ='Export-dataset'!C9 -> 1646
A18: Export | B18: 2022 | C18: 00 | D18: sub | E18: Live animals (excl. fish (not marine mammals) crustaceans, molluscs and aquatic invertebrates of SITC Division 03) | F18: $ Millions | G18: A1827805L | H18: ='Export-dataset'!C10 -> 1518
A19: Export | B19: 2023 | C19: 00 | D19: sub | E19: Live animals (excl. fish (not marine mammals) crustaceans, molluscs and aquatic invertebrates of SITC Division 03) | F19: $ Millions | G19: A1827805L | H19: ='Export-dataset'!C11 -> 1236
A20: Export | B20: 2024 | C20: 00 | D20: sub | E20: Live animals (excl. fish (not marine mammals) crustaceans, molluscs and aquatic invertebrates of SITC Division 03) | F20: $ Millions | G20: A1827805L | H20: ='Export-dataset'!C12 -> 1117
A21: Export | B21: 2025 | C21: 00 | D21: sub | E21: Live animals (excl. fish (not marine mammals) crustaceans, molluscs and aquatic invertebrates of SITC Division 03) | F21: $ Millions | G21: A1827805L | H21: ='Export-dataset'!C13 -> 1299
A22: Export | B22: 2016 | C22: 01 | D22: sub | E22: Meat and meat preparations | F22: $ Millions | G22: A1827806R | H22: ='Export-dataset'!D4 -> 11088
A23: Export | B23: 2017 | C23: 01 | D23: sub | E23: Meat and meat preparations | F23: $ Millions | G23: A1827806R | H23: ='Export-dataset'!D5 -> 11834
A24: Export | B24: 2018 | C24: 01 | D24: sub | E24: Meat and meat preparations | F24: $ Millions | G24: A1827806R | H24: ='Export-dataset'!D6 -> 13605
A25: Export | B25: 2019 | C25: 01 | D25: sub | E25: Meat and meat preparations | F25: $ Millions | G25: A1827806R | H25: ='Export-dataset'!D7 -> 16462
A26: Export | B26: 2020 | C26: 01 | D26: sub | E26: Meat and meat preparations | F26: $ Millions | G26: A1827806R | H26: ='Export-dataset'!D8 -> 14705
A27: Export | B27: 2021 | C27: 01 | D27: sub | E27: Meat and meat preparations | F27: $ Millions | G27: A1827806R | H27: ='Export-dataset'!D9 -> 14801
A28: Export | B28: 2022 | C28: 01 | D28: sub | E28: Meat and meat preparations | F28: $ Millions | G28: A1827806R | H28: ='Export-dataset'!D10 -> 16600
A29: Export | B29: 2023 | C29: 01 | D29: sub | E29: Meat and meat preparations | F29: $ Millions | G29: A1827806R | H29: ='Export-dataset'!D11 -> 17798
A30: Export | B30: 2024 | C30: 01 | D30: sub | E30: Meat and meat preparations | F30: $ Millions | G30: A1827806R | H30: ='Export-dataset'!D12 -> 21317
A31: Export | B31: 2025 | C31: 01 | D31: sub | E31: Meat and meat preparations | F31: $ Millions | G31: A1827806R | H31: ='Export-dataset'!D13 -> 27217
A32: Export | B32: 2016 | C32: 02 | D32: sub | E32: Dairy products and birds’ eggs | F32: $ Millions | G32: A1827807T | H32: ='Export-dataset'!E4 -> 2208
A33: Export | B33: 2017 | C33: 02 | D33: sub | E33: Dairy products and birds’ eggs | F33: $ Millions | G33: A1827807T | H33: ='Export-dataset'!E5 -> 2345
A34: Export | B34: 2018 | C34: 02 | D34: sub | E34: Dairy products and birds’ eggs | F34: $ Millions | G34: A1827807T | H34: ='Export-dataset'!E6 -> 2481
A35: Export | B35: 2019 | C35: 02 | D35: sub | E35: Dairy products and birds’ eggs | F35: $ Millions | G35: A1827807T | H35: ='Export-dataset'!E7 -> 2488
A36: Export | B36: 2020 | C36: 02 | D36: sub | E36: Dairy products and birds’ eggs | F36: $ Millions | G36: A1827807T | H36: ='Export-dataset'!E8 -> 2544
A37: Export | B37: 2021 | C37: 02 | D37: sub | E37: Dairy products and birds’ eggs | F37: $ Millions | G37: A1827807T | H37: ='Export-dataset'!E9 -> 2947
A38: Export | B38: 2022 | C38: 02 | D38: sub | E38: Dairy products and birds’ eggs | F38: $ Millions | G38: A1827807T | H38: ='Export-dataset'!E10 -> 3385
A39: Export | B39: 2023 | C39: 02 | D39: sub | E39: Dairy products and birds’ eggs | F39: $ Millions | G39: A1827807T | H39: ='Export-dataset'!E11 -> 3000
A40: Export | B40: 2024 | C40: 02 | D40: sub | E40: Dairy products and birds’ eggs | F40: $ Millions | G40: A1827807T | H40: ='Export-dataset'!E12 -> 3425
...

Sheet Import-tidy
A1: Direction | B1: Year | C1: Code | D1: Level | E1: Category | F1: Unit | G1: Series ID | H1: Value ($ Millions, import)
A2: Import | B2: 2016 | C2: 0 | D2: main | E2: Food and live animals | F2: $ Millions | G2: A1828644C | H2: ='Import-dataset'!B4 -> 13977
A3: Import | B3: 2017 | C3: 0 | D3: main | E3: Food and live animals | F3: $ Millions | G3: A1828644C | H3: ='Import-dataset'!B5 -> 14304
A4: Import | B4: 2018 | C4: 0 | D4: main | E4: Food and live animals | F4: $ Millions | G4: A1828644C | H4: ='Import-dataset'!B6 -> 15132
A5: Import | B5: 2019 | C5: 0 | D5: main | E5: Food and live animals | F5: $ Millions | G5: A1828644C | H5: ='Import-dataset'!B7 -> 16938
A6: Import | B6: 2020 | C6: 0 | D6: main | E6: Food and live animals | F6: $ Millions | G6: A1828644C | H6: ='Import-dataset'!B8 -> 17607
A7: Import | B7: 2021 | C7: 0 | D7: main | E7: Food and live animals | F7: $ Millions | G7: A1828644C | H7: ='Import-dataset'!B9 -> 16410
A8: Import | B8: 2022 | C8: 0 | D8: main | E8: Food and live animals | F8: $ Millions | G8: A1828644C | H8: ='Import-dataset'!B10 -> 19518
A9: Import | B9: 2023 | C9: 0 | D9: main | E9: Food and live animals | F9: $ Millions | G9: A1828644C | H9: ='Import-dataset'!B11 -> 19684
A10: Import | B10: 2024 | C10: 0 | D10: main | E10: Food and live animals | F10: $ Millions | G10: A1828644C | H10: ='Import-dataset'!B12 -> 22293
A11: Import | B11: 2025 | C11: 0 | D11: main | E11: Food and live animals | F11: $ Millions | G11: A1828644C | H11: ='Import-dataset'!B13 -> 24515
A12: Import | B12: 2016 | C12: 00 | D12: sub | E12: Live animals (excl. fish (not marine mammals) crustaceans, molluscs and aquatic invertebrates of SITC Division 03) | F12: $ Millions | G12: A1828645F | H12: ='Import-dataset'!C4 -> 121
A13: Import | B13: 2017 | C13: 00 | D13: sub | E13: Live animals (excl. fish (not marine mammals) crustaceans, molluscs and aquatic invertebrates of SITC Division 03) | F13: $ Millions | G13: A1828645F | H13: ='Import-dataset'!C5 -> 155
A14: Import | B14: 2018 | C14: 00 | D14: sub | E14: Live animals (excl. fish (not marine mammals) crustaceans, molluscs and aquatic invertebrates of SITC Division 03) | F14: $ Millions | G14: A1828645F | H14: ='Import-dataset'!C6 -> 168
A15: Import | B15: 2019 | C15: 00 | D15: sub | E15: Live animals (excl. fish (not marine mammals) crustaceans, molluscs and aquatic invertebrates of SITC Division 03) | F15: $ Millions | G15: A1828645F | H15: ='Import-dataset'!C7 -> 145
A16: Import | B16: 2020 | C16: 00 | D16: sub | E16: Live animals (excl. fish (not marine mammals) crustaceans, molluscs and aquatic invertebrates of SITC Division 03) | F16: $ Millions | G16: A1828645F | H16: ='Import-dataset'!C8 -> 157
A17: Import | B17: 2021 | C17: 00 | D17: sub | E17: Live animals (excl. fish (not marine mammals) crustaceans, molluscs and aquatic invertebrates of SITC Division 03) | F17: $ Millions | G17: A1828645F | H17: ='Import-dataset'!C9 -> 156
A18: Import | B18: 2022 | C18: 00 | D18: sub | E18: Live animals (excl. fish (not marine mammals) crustaceans, molluscs and aquatic invertebrates of SITC Division 03) | F18: $ Millions | G18: A1828645F | H18: ='Import-dataset'!C10 -> 167
A19: Import | B19: 2023 | C19: 00 | D19: sub | E19: Live animals (excl. fish (not marine mammals) crustaceans, molluscs and aquatic invertebrates of SITC Division 03) | F19: $ Millions | G19: A1828645F | H19: ='Import-dataset'!C11 -> 212
A20: Import | B20: 2024 | C20: 00 | D20: sub | E20: Live animals (excl. fish (not marine mammals) crustaceans, molluscs and aquatic invertebrates of SITC Division 03) | F20: $ Millions | G20: A1828645F | H20: ='Import-dataset'!C12 -> 201
A21: Import | B21: 2025 | C21: 00 | D21: sub | E21: Live animals (excl. fish (not marine mammals) crustaceans, molluscs and aquatic invertebrates of SITC Division 03) | F21: $ Millions | G21: A1828645F | H21: ='Import-dataset'!C13 -> 190
A22: Import | B22: 2016 | C22: 01 | D22: sub | E22: Meat and meat preparations | F22: $ Millions | G22: A1828646J | H22: ='Import-dataset'!D4 -> 780
A23: Import | B23: 2017 | C23: 01 | D23: sub | E23: Meat and meat preparations | F23: $ Millions | G23: A1828646J | H23: ='Import-dataset'!D5 -> 833
A24: Import | B24: 2018 | C24: 01 | D24: sub | E24: Meat and meat preparations | F24: $ Millions | G24: A1828646J | H24: ='Import-dataset'!D6 -> 822
A25: Import | B25: 2019 | C25: 01 | D25: sub | E25: Meat and meat preparations | F25: $ Millions | G25: A1828646J | H25: ='Import-dataset'!D7 -> 1029
A26: Import | B26: 2020 | C26: 01 | D26: sub | E26: Meat and meat preparations | F26: $ Millions | G26: A1828646J | H26: ='Import-dataset'!D8 -> 905
A27: Import | B27: 2021 | C27: 01 | D27: sub | E27: Meat and meat preparations | F27: $ Millions | G27: A1828646J | H27: ='Import-dataset'!D9 -> 966
A28: Import | B28: 2022 | C28: 01 | D28: sub | E28: Meat and meat preparations | F28: $ Millions | G28: A1828646J | H28: ='Import-dataset'!D10 -> 1070
A29: Import | B29: 2023 | C29: 01 | D29: sub | E29: Meat and meat preparations | F29: $ Millions | G29: A1828646J | H29: ='Import-dataset'!D11 -> 1035
A30: Import | B30: 2024 | C30: 01 | D30: sub | E30: Meat and meat preparations | F30: $ Millions | G30: A1828646J | H30: ='Import-dataset'!D12 -> 1251
A31: Import | B31: 2025 | C31: 01 | D31: sub | E31: Meat and meat preparations | F31: $ Millions | G31: A1828646J | H31: ='Import-dataset'!D13 -> 1252
A32: Import | B32: 2016 | C32: 02 | D32: sub | E32: Dairy products and birds’ eggs | F32: $ Millions | G32: A1828647K | H32: ='Import-dataset'!E4 -> 1075
A33: Import | B33: 2017 | C33: 02 | D33: sub | E33: Dairy products and birds’ eggs | F33: $ Millions | G33: A1828647K | H33: ='Import-dataset'!E5 -> 1321
A34: Import | B34: 2018 | C34: 02 | D34: sub | E34: Dairy products and birds’ eggs | F34: $ Millions | G34: A1828647K | H34: ='Import-dataset'!E6 -> 1420
A35: Import | B35: 2019 | C35: 02 | D35: sub | E35: Dairy products and birds’ eggs | F35: $ Millions | G35: A1828647K | H35: ='Import-dataset'!E7 -> 1477
A36: Import | B36: 2020 | C36: 02 | D36: sub | E36: Dairy products and birds’ eggs | F36: $ Millions | G36: A1828647K | H36: ='Import-dataset'!E8 -> 1589
A37: Import | B37: 2021 | C37: 02 | D37: sub | E37: Dairy products and birds’ eggs | F37: $ Millions | G37: A1828647K | H37: ='Import-dataset'!E9 -> 1438
A38: Import | B38: 2022 | C38: 02 | D38: sub | E38: Dairy products and birds’ eggs | F38: $ Millions | G38: A1828647K | H38: ='Import-dataset'!E10 -> 1809
A39: Import | B39: 2023 | C39: 02 | D39: sub | E39: Dairy products and birds’ eggs | F39: $ Millions | G39: A1828647K | H39: ='Import-dataset'!E11 -> 2034
A40: Import | B40: 2024 | C40: 02 | D40: sub | E40: Dairy products and birds’ eggs | F40: $ Millions | G40: A1828647K | H40: ='Import-dataset'!E12 -> 1935
...

Sheet Main-Analytics
A1: Main category analytics, import and export
A2: Every cell is a live formula that reads the two dataset sheets. Values are in $ Millions unless the block says otherwise.
A4: Export: value ($ Millions)
A5: Code | B5: Category | C5: 2016 | D5: 2017 | E5: 2018 | F5: 2019 | G5: 2020 | H5: 2021 | I5: 2022 | J5: 2023 | K5: 2024 | L5: 2025
A6: 0 | B6: Food and live animals | C6: ='Export-dataset'!B4 -> 32621 | D6: ='Export-dataset'!B5 -> 36596 | E6: ='Export-dataset'!B6 -> 35271 | F6: ='Export-dataset'!B7 -> 37649 | G6: ='Export-dataset'!B8 -> 35628 | H6: ='Export-dataset'!B9 -> 43540 | I6: ='Export-dataset'!B10 -> 53122 | J6: ='Export-dataset'!B11 -> 54749 | K6: ='Export-dataset'!B12 -> 52562 | L6: ='Export-dataset'!B13 -> 62043
A7: 1 | B7: Beverages and tobacco | C7: ='Export-dataset'!M4 -> 2679 | D7: ='Export-dataset'!M5 -> 3031 | E7: ='Export-dataset'!M6 -> 3377 | F7: ='Export-dataset'!M7 -> 3582 | G7: ='Export-dataset'!M8 -> 3283 | H7: ='Export-dataset'!M9 -> 2523 | I7: ='Export-dataset'!M10 -> 2572 | J7: ='Export-dataset'!M11 -> 2548 | K7: ='Export-dataset'!M12 -> 3179 | L7: ='Export-dataset'!M13 -> 3066
A8: 2 | B8: Crude materials, inedible, except fuels | C8: ='Export-dataset'!P4 -> 83621 | D8: ='Export-dataset'!P5 -> 99473 | E8: ='Export-dataset'!P6 -> 106879 | F8: ='Export-dataset'!P7 -> 136415 | G8: ='Export-dataset'!P8 -> 151968 | H8: ='Export-dataset'!P9 -> 198179 | I8: ='Export-dataset'!P10 -> 188296 | J8: ='Export-dataset'!P11 -> 202961 | K8: ='Export-dataset'!P12 -> 179588 | L8: ='Export-dataset'!P13 -> 180651
A9: 3 | B9: Mineral fuels, lubricants and related materials | C9: ='Export-dataset'!Z4 -> 67702 | D9: ='Export-dataset'!Z5 -> 91149 | E9: ='Export-dataset'!Z6 -> 122269 | F9: ='Export-dataset'!Z7 -> 126288 | G9: ='Export-dataset'!Z8 -> 88821 | H9: ='Export-dataset'!Z9 -> 126395 | I9: ='Export-dataset'!Z10 -> 251334 | J9: ='Export-dataset'!Z11 -> 195549 | K9: ='Export-dataset'!Z12 -> 170842 | L9: ='Export-dataset'!Z13 -> 140181
A10: 4 | B10: Animal and vegetable oils, fats and waxes | C10: ='Export-dataset'!AD4 -> 675 | D10: ='Export-dataset'!AD5 -> 680 | E10: ='Export-dataset'!AD6 -> 663 | F10: ='Export-dataset'!AD7 -> 647 | G10: ='Export-dataset'!AD8 -> 761 | H10: ='Export-dataset'!AD9 -> 1085 | I10: ='Export-dataset'!AD10 -> 1682 | J10: ='Export-dataset'!AD11 -> 1609 | K10: ='Export-dataset'!AD12 -> 1397 | L10: ='Export-dataset'!AD13 -> 1806
A11: 5 | B11: Chemicals and related products, nes | C11: ='Export-dataset'!AH4 -> 8367 | D11: ='Export-dataset'!AH5 -> 8643 | E11: ='Export-dataset'!AH6 -> 10510 | F11: ='Export-dataset'!AH7 -> 11971 | G11: ='Export-dataset'!AH8 -> 11092 | H11: ='Export-dataset'!AH9 -> 10052 | I11: ='Export-dataset'!AH10 -> 12575 | J11: ='Export-dataset'!AH11 -> 11484 | K11: ='Export-dataset'!AH12 -> 12272 | L11: ='Export-dataset'!AH13 -> 12141
A12: 6 | B12: Manufactured goods classified chiefly by material | C12: ='Export-dataset'!AR4 -> 13406 | D12: ='Export-dataset'!AR5 -> 14749 | E12: ='Export-dataset'!AR6 -> 17031 | F12: ='Export-dataset'!AR7 -> 17567 | G12: ='Export-dataset'!AR8 -> 14708 | H12: ='Export-dataset'!AR9 -> 16703 | I12: ='Export-dataset'!AR10 -> 19431 | J12: ='Export-dataset'!AR11 -> 19357 | K12: ='Export-dataset'!AR12 -> 20515 | L12: ='Export-dataset'!AR13 -> 22719
A13: 7 | B13: Machinery and transport equipment | C13: ='Export-dataset'!BB4 -> 15387 | D13: ='Export-dataset'!BB5 -> 14638 | E13: ='Export-dataset'!BB6 -> 15352 | F13: ='Export-dataset'!BB7 -> 16992 | G13: ='Export-dataset'!BB8 -> 14678 | H13: ='Export-dataset'!BB9 -> 14728 | I13: ='Export-dataset'!BB10 -> 16516 | J13: ='Export-dataset'!BB11 -> 18604 | K13: ='Export-dataset'!BB12 -> 20484 | L13: ='Export-dataset'!BB13 -> 22210
A14: 8 | B14: Miscellaneous manufactured articles | C14: ='Export-dataset'!BL4 -> 6558 | D14: ='Export-dataset'!BL5 -> 6857 | E14: ='Export-dataset'!BL6 -> 7288 | F14: ='Export-dataset'!BL7 -> 8208 | G14: ='Export-dataset'!BL8 -> 7376 | H14: ='Export-dataset'!BL9 -> 8036 | I14: ='Export-dataset'!BL10 -> 9077 | J14: ='Export-dataset'!BL11 -> 10517 | K14: ='Export-dataset'!BL12 -> 10974 | L14: ='Export-dataset'!BL13 -> 11863
A15: 9 | B15: Commodities and transactions not classified elsewhere in the SITC | C15: ='Export-dataset'!BU4 -> 27452 | D15: ='Export-dataset'!BU5 -> 25523 | E15: ='Export-dataset'!BU6 -> 25975 | F15: ='Export-dataset'!BU7 -> 30661 | G15: ='Export-dataset'!BU8 -> 34408 | H15: ='Export-dataset'!BU9 -> 36933 | I15: ='Export-dataset'!BU10 -> 39255 | J15: ='Export-dataset'!BU11 -> 41247 | K15: ='Export-dataset'!BU12 -> 45169 | L15: ='Export-dataset'!BU13 -> 66414
A17: Export: year on year growth
A18: Code | B18: Category | C18: 2017 | D18: 2018 | E18: 2019 | F18: 2020 | G18: 2021 | H18: 2022 | I18: 2023 | J18: 2024 | K18: 2025
A19: 0 | B19: Food and live animals | C19: =IFERROR('Export-dataset'!B5/'Export-dataset'!B4-1,"") -> 0.12185402 | D19: =IFERROR('Export-dataset'!B6/'Export-dataset'!B5-1,"") -> -0.036206143 | E19: =IFERROR('Export-dataset'!B7/'Export-dataset'!B6-1,"") -> 0.067420827 | F19: =IFERROR('Export-dataset'!B8/'Export-dataset'!B7-1,"") -> -0.053680045 | G19: =IFERROR('Export-dataset'!B9/'Export-dataset'!B8-1,"") -> 0.22207253 | H19: =IFERROR('Export-dataset'!B10/'Export-dataset'!B9-1,"") -> 0.2200735 | I19: =IFERROR('Export-dataset'!B11/'Export-dataset'!B10-1,"") -> 0.030627612 | J19: =IFERROR('Export-dataset'!B12/'Export-dataset'!B11-1,"") -> -0.039945935 | K19: =IFERROR('Export-dataset'!B13/'Export-dataset'!B12-1,"") -> 0.18037746
A20: 1 | B20: Beverages and tobacco | C20: =IFERROR('Export-dataset'!M5/'Export-dataset'!M4-1,"") -> 0.13139231 | D20: =IFERROR('Export-dataset'!M6/'Export-dataset'!M5-1,"") -> 0.11415374 | E20: =IFERROR('Export-dataset'!M7/'Export-dataset'!M6-1,"") -> 0.060704768 | F20: =IFERROR('Export-dataset'!M8/'Export-dataset'!M7-1,"") -> -0.08347292 | G20: =IFERROR('Export-dataset'!M9/'Export-dataset'!M8-1,"") -> -0.23149558 | H20: =IFERROR('Export-dataset'!M10/'Export-dataset'!M9-1,"") -> 0.019421324 | I20: =IFERROR('Export-dataset'!M11/'Export-dataset'!M10-1,"") -> -0.0093312597 | J20: =IFERROR('Export-dataset'!M12/'Export-dataset'!M11-1,"") -> 0.24764521 | K20: =IFERROR('Export-dataset'!M13/'Export-dataset'!M12-1,"") -> -0.035545769
A21: 2 | B21: Crude materials, inedible, except fuels | C21: =IFERROR('Export-dataset'!P5/'Export-dataset'!P4-1,"") -> 0.18956961 | D21: =IFERROR('Export-dataset'!P6/'Export-dataset'!P5-1,"") -> 0.074452364 | E21: =IFERROR('Export-dataset'!P7/'Export-dataset'!P6-1,"") -> 0.27634989 | F21: =IFERROR('Export-dataset'!P8/'Export-dataset'!P7-1,"") -> 0.11401239 | G21: =IFERROR('Export-dataset'!P9/'Export-dataset'!P8-1,"") -> 0.30408375 | H21: =IFERROR('Export-dataset'!P10/'Export-dataset'!P9-1,"") -> -0.049869058 | I21: =IFERROR('Export-dataset'!P11/'Export-dataset'!P10-1,"") -> 0.077882695 | J21: =IFERROR('Export-dataset'!P12/'Export-dataset'!P11-1,"") -> -0.11516006 | K21: =IFERROR('Export-dataset'!P13/'Export-dataset'!P12-1,"") -> 0.0059191037
A22: 3 | B22: Mineral fuels, lubricants and related materials | C22: =IFERROR('Export-dataset'!Z5/'Export-dataset'!Z4-1,"") -> 0.34632655 | D22: =IFERROR('Export-dataset'!Z6/'Export-dataset'!Z5-1,"") -> 0.341419 | E22: =IFERROR('Export-dataset'!Z7/'Export-dataset'!Z6-1,"") -> 0.032870147 | F22: =IFERROR('Export-dataset'!Z8/'Export-dataset'!Z7-1,"") -> -0.29667902 | G22: =IFERROR('Export-dataset'!Z9/'Export-dataset'!Z8-1,"") -> 0.42303059 | H22: =IFERROR('Export-dataset'!Z10/'Export-dataset'!Z9-1,"") -> 0.98848056 | I22: =IFERROR('Export-dataset'!Z11/'Export-dataset'!Z10-1,"") -> -0.22195564 | J22: =IFERROR('Export-dataset'!Z12/'Export-dataset'!Z11-1,"") -> -0.12634685 | K22: =IFERROR('Export-dataset'!Z13/'Export-dataset'!Z12-1,"") -> -0.17946992
A23: 4 | B23: Animal and vegetable oils, fats and waxes | C23: =IFERROR('Export-dataset'!AD5/'Export-dataset'!AD4-1,"") -> 0.0074074074 | D23: =IFERROR('Export-dataset'!AD6/'Export-dataset'!AD5-1,"") -> -0.025 | E23: =IFERROR('Export-dataset'!AD7/'Export-dataset'!AD6-1,"") -> -0.02413273 | F23: =IFERROR('Export-dataset'!AD8/'Export-dataset'!AD7-1,"") -> 0.17619784 | G23: =IFERROR('Export-dataset'!AD9/'Export-dataset'!AD8-1,"") -> 0.42575558 | H23: =IFERROR('Export-dataset'!AD10/'Export-dataset'!AD9-1,"") -> 0.55023041 | I23: =IFERROR('Export-dataset'!AD11/'Export-dataset'!AD10-1,"") -> -0.043400713 | J23: =IFERROR('Export-dataset'!AD12/'Export-dataset'!AD11-1,"") -> -0.13175886 | K23: =IFERROR('Export-dataset'!AD13/'Export-dataset'!AD12-1,"") -> 0.29277022
A24: 5 | B24: Chemicals and related products, nes | C24: =IFERROR('Export-dataset'!AH5/'Export-dataset'!AH4-1,"") -> 0.032986734 | D24: =IFERROR('Export-dataset'!AH6/'Export-dataset'!AH5-1,"") -> 0.21601296 | E24: =IFERROR('Export-dataset'!AH7/'Export-dataset'!AH6-1,"") -> 0.13901047 | F24: =IFERROR('Export-dataset'!AH8/'Export-dataset'!AH7-1,"") -> -0.07342745 | G24: =IFERROR('Export-dataset'!AH9/'Export-dataset'!AH8-1,"") -> -0.093761269 | H24: =IFERROR('Export-dataset'!AH10/'Export-dataset'!AH9-1,"") -> 0.25099483 | I24: =IFERROR('Export-dataset'!AH11/'Export-dataset'!AH10-1,"") -> -0.086759443 | J24: =IFERROR('Export-dataset'!AH12/'Export-dataset'!AH11-1,"") -> 0.068617207 | K24: =IFERROR('Export-dataset'!AH13/'Export-dataset'!AH12-1,"") -> -0.010674707
